Workbook

Sheet 1008-403
A1: Date | B1: Journal | C1: Ref. | D1: Description | E1: Cost Center | F1: Debit | G1: Credit | H1: Balance
A2: Account Code : 1008/403 Account Name : SYNTHETICS LATEX
D3: Balance B/F | F3: 0 | G3: 0 | H3: 10139364
A4: 01-May-26 | B4: JV-26-05-0028 | C4: Beginning Stock Compound Latex, Dispersion, Production dept of May'26 | D4: Beginning Stock Compound latex in Compound dept of May'26 | F4: 0 | G4: 1687850.2 | H4: 8451513.4
A5: 01-May-26 | B5: JV-26-05-0028 | C5: Beginning Stock Compound Latex, Dispersion, Production dept of May'26 | D5: Beginning Stock Compound latex in Dipping lines of May'26 | F5: 0 | G5: 190811.58 | H5: 8260701.8
A6: 31-May-26 | B6: JV-26-05-0125 | C6: Trf NBR LATEX FROM P1,P2and P3 on May'26 | D6: Trf NBR LATEX FROM STORE-P2 TO COM-P1 128,030 KG on May'26 | F6: 6777780.2 | G6: 0 | H6: 15038482
A7: 31-May-26 | B7: JV-26-05-0125 | C7: Trf NBR LATEX FROM P1,P2and P3 on May'26 | D7: Trf NBR LATEX FROM STORE-P3 TO COM-P1 155,710 KG on May'26 | F7: 6804835.8 | G7: 0 | H7: 21843318
A8: 31-May-26 | B8: JV-26-05-0125 | C8: Trf NBR LATEX FROM P1,P2and P3 on May'26 | D8: Trf NBR LATEX FROM COM-P3 TO COM-P1 4,671 KG on May'26 | F8: 468421.56 | G8: 0 | H8: 22311739
A9: 31-May-26 | B9: JV-26-05-0125 | C9: Trf NBR LATEX FROM P1,P2and P3 on May'26 | D9: Trf NBR LATEX FROM COM-P2 TO COM-P1 35,945 KG on May'26 | F9: 1431570.1 | G9: 0 | H9: 23743310
A10: 31-May-26 | B10: JV-26-05-0125 | C10: Trf NBR LATEX FROM P1,P2and P3 on May'26 | D10: Trf NBR LATEX FROM COM-P1 TO COM-P2 30,760 KG on May'26 | F10: 0 | G10: 1205649.2 | H10: 22537660
A11: 31-May-26 | B11: JV-26-05-0125 | C11: Trf NBR LATEX FROM P1,P2and P3 on May'26 | D11: Trf NBR LATEX FROM COM-P1 TO COM-P3 29,879 KG on May'26 | F11: 0 | G11: 691743.98 | H11: 21845916
A12: 31-May-26 | B12: JV-26-05-0150 | C12: Ending Balance Stock NBR and Chemical and Use of Plant 1 on May'26 | D12: Balance Compound latex in Compound dept of May'26 | F12: 1920167.2 | G12: 0 | H12: 23766084
A13: 31-May-26 | B13: JV-26-05-0150 | C13: Ending Balance Stock NBR and Chemical and Use of Plant 1 on May'26 | D13: Balance Compound latex in Dipping lines of May'26 | F13: 328050.82 | G13: 0 | H13: 24094134
A14: 31-May-26 | B14: JV-26-05-0150 | C14: Ending Balance Stock NBR and Chemical and Use of Plant 1 on May'26 | D14: Record Issue NBR latex-Comp from stock card Com P1 of May'26 | F14: 0 | G14: 13082080 | H14: 11012054
E15: Total | F15: 17730826 | G15: 16858135
E16: Grand Total | F16: 17730826 | G16: 16858135
A17: Printed by Siriporn Boonrath On 05-Jun-2026 09:52:26 PM | B17: Page -1 of 1
F23: Balance stock Compound | H23: ='NBR Latex-Comp'!BB13 -> 8763836.2
F24: Balance stock Dip+Com | H24: =Used_before_Trf!AB174 -> 2248218
F25: Total | H25: =SUM(H23:H24) -> 11012054
F26: Diff | H26: =H14-H25 -> -0.08
F43: 0

Sheet 7000-131
A1: Date | B1: Journal | C1: Ref. | D1: Description | E1: Cost Center | F1: Debit | G1: Credit | H1: Balance
A2: Account Code : 7000/131 Account Name : PURCHASE SYNTHETICS LATEX
D3: Balance B/F | F3: 0 | G3: 0 | H3: 5797752.7
A4: 01-Feb-26 | B4: JV-26-02-0022 | C4: ฺBeginning Stock NBR Latex and Chemical of Plant 1 on Feb'26 | D4: Beginning Stock Compound latex in Compound dept of Feb'26 | E4: Compounding P1 | F4: 585463.38 | G4: 0 | H4: 6383216
A5: 01-Feb-26 | B5: JV-26-02-0022 | C5: ฺBeginning Stock NBR Latex and Chemical of Plant 1 on Feb'26 | D5: Beginning Stock Compound latex in Dipping lines of Feb'26 | E5: Compounding P1 | F5: 97513.91 | G5: 0 | H5: 6480729.9
A6: 28-Feb-26 | B6: JV-26-02-0126 | C6: Ending Balance Stock NBR and Chemical and Use of Plant 1 on Feb'26 | D6: Balance Compound latex in Compound dept of Feb'26 | E6: Compounding P1 | F6: 0 | G6: 709416.42 | H6: 5771313.5
A7: 28-Feb-26 | B7: JV-26-02-0126 | C7: Ending Balance Stock NBR and Chemical and Use of Plant 1 on Feb'26 | D7: Record Issue NBR latex-Comp from stock card Com P1 of Feb'26 | E7: Compounding P1 | F7: 5435567.4 | G7: 0 | H7: 11206881
A8: 28-Feb-26 | B8: JV-26-02-0126 | C8: Ending Balance Stock NBR and Chemical and Use of Plant 1 on Feb'26 | D8: Balance Compound latex in Dipping lines of Feb'26 | E8: Compounding P1 | F8: 0 | G8: 144751.7 | H8: 11062129
A9: 28-Feb-26 | B9: JV-26-02-0131 | C9: Transfer Compound latex and Dispersion between plants of Feb'26 | D9: Transfer Compound latex between plants of Feb'26 | E9: Compounding P1 | F9: 66456.8 | G9: 0 | H9: 11128586
E10: Total | F10: 6185001.5 | G10: 854168.12
E11: Grand Total | F11: 6185001.5 | G11: 854168.12
A12: Printed by Siriporn Boonrath On 06-Mar-2026 10:03:26 AM | B12: Page -1 of 1
F13: =F11-G11 -> 5330833.4

Sheet 1008-402
A1: Date | B1: Journal | C1: Ref. | D1: Description | E1: Cost Center | F1: Debit | G1: Credit | H1: Balance
A2: Account Code : 1008/402 Account Name : CHEMICAL FOR NR GLOVES
D3: Balance B/F | F3: 0 | G3: 0 | H3: 2577038.9
A4: 01-May-26 | B4: JV-26-05-0028 | C4: Beginning Stock Compound Latex, Dispersion, Production dept of May'26 | D4: Beginning Stock Compound latex in Compound dept of May'26 | F4: 0 | G4: 155765.77 | H4: 2421273.1
A5: 01-May-26 | B5: JV-26-05-0028 | C5: Beginning Stock Compound Latex, Dispersion, Production dept of May'26 | D5: Beginning Stock Dispersion in Compound dept of May'26 | F5: 0 | G5: 312388.52 | H5: 2108884.6
A6: 01-May-26 | B6: JV-26-05-0028 | C6: Beginning Stock Compound Latex, Dispersion, Production dept of May'26 | D6: Beginning Stock Compound latex in Dipping lines of May'26 | F6: 0 | G6: 17696.49 | H6: 2091188.1
A7: 01-May-26 | B7: JV-26-05-0028 | C7: Beginning Stock Compound Latex, Dispersion, Production dept of May'26 | D7: Beginning Stock Compound latex in Dipping lines of May'26 | F7: 0 | G7: 55899.52 | H7: 2035288.6
A8: 01-May-26 | B8: JV-26-05-0028 | C8: Beginning Stock Compound Latex, Dispersion, Production dept of May'26 | D8: Beginning Stock Chemical in Production May'26 | F8: 0 | G8: 67687.75 | H8: 1967600.8
A9: 06-May-26 | B9: MIJ-26-05-0086 | C9: MI-26-05-0092 | D9: TEXKLEEN P22 (225KG/DRUM)(ALKALINE CLEANER ),(TEST) KLEEN S21 (225KG/DRUM) (ALAKLINE CLEANNER) | F9: 0 | G9: 18000 | H9: 1949600.8
A10: 09-May-26 | B10: MIJ-26-05-0175 | C10: MI-26-05-0187 | D10: TEXKLEEN P22 (225KG/DRUM)(ALKALINE CLEANER ) | F10: 0 | G10: 9450 | H10: 1940150.8
A11: 11-May-26 | B11: MIJ-26-05-0176 | C11: MI-26-05-0188 | D11: TEXKLEEN P22 (225KG/DRUM)(ALKALINE CLEANER ) | F11: 0 | G11: 9450 | H11: 1930700.8
A12: 13-May-26 | B12: MIJ-26-05-0268 | C12: MI-26-05-0292 | D12: NITRIC ACID 68% (280 KGS/DRUM ) | F12: 0 | G12: 17360 | H12: 1913340.8
A13: 15-May-26 | B13: MIJ-26-05-0314 | C13: MI-26-05-0345 | D13: (TEST) SPECLEAN 10 (230KG/DRUM) - ALKALINE CLEANER | F13: 0 | G13: 8834.39 | H13: 1904506.4
A14: 18-May-26 | B14: MIJ-26-05-0420 | C14: MI-26-05-0469 | D14: (TEST) SPECLEAN 10 (230KG/DRUM) - ALKALINE CLEANER,TEXKLEEN P22 (225KG/DRUM)(ALKALINE CLEANER ) | F14: 0 | G14: 18284.39 | H14: 1886222
A15: 19-May-26 | B15: PUR-26-05-0879 | C15: PS-26-05-0649 | D15: INV.NU-INV-1065-B BIO-F20 (100KG) - NUECHEMIE | F15: 13709.36 | G15: 0 | H15: 1899931.4
... A34: 31-May-26 | B34: JV-26-05-0150 | C34: Ending Balance Stock NBR and Chemical and Use of Plant 1 on May'26 | D34: Record Issue Che-Comp from stock card Com P1 of May'26 | F34: 781.78 | G34: 0 | H34: 2816697.8
E35: Total | F35: 4487328.2 | G35: 4247669.2
E36: Grand Total | F36: 4487328.2 | G36: 4247669.2
A37: Printed by Siriporn Boonrath On 05-Jun-2026 09:52:59 PM | B37: Page -1 of 1
E38: Purchase | F38: =F36-F34-F32-F31-F30-F29-F28-F27-F25-F24-F23 -> 1303811.2
F40: Balance Stock Store | H40: ='Che-Store'!BC14 -> 1641528.2
F41: Balance Stock Compound | H41: ='Che-Comp'!BC30 -> 524568.67
F42: Balance stock Dip+Com | H42: =Used_before_Trf!AB172 -> 608636.2
F43: Balance stock production | H43: ='Che.-Prod'!R18 -> 41966
F44: Total | H44: =SUM(H40:H43) -> 2816699
F45: Diff | H45: =H34-H44 -> -1.22

Sheet 7000-122
A1: Date | B1: Journal | C1: Ref. | D1: Description | E1: Cost Center | F1: Debit | G1: Credit | H1: Balance
A2: Account Code : 7000/122 Account Name : PURCHASES - CHEMICAL
D3: Balance B/F | F3: 0 | G3: 0 | H3: 31410909
A4: 01-Feb-26 | B4: JV-26-02-0022 | C4: ฺBeginning Stock NBR Latex and Chemical of Plant 1 on Feb'26 | D4: Beginning Stock Compound latex in Compound dept of Feb'26 | E4: Compounding P1 | F4: 96744.25 | G4: 0 | H4: 31507653
A5: 01-Feb-26 | B5: JV-26-02-0022 | C5: ฺBeginning Stock NBR Latex and Chemical of Plant 1 on Feb'26 | D5: Beginning Stock Dispersion in Compound dept of Feb'26 | E5: Compounding P1 | F5: 100662.71 | G5: 0 | H5: 31608316
A6: 01-Feb-26 | B6: JV-26-02-0022 | C6: ฺBeginning Stock NBR Latex and Chemical of Plant 1 on Feb'26 | D6: Beginning Stock Compound latex in Dipping lines of Feb'26 | E6: Compounding P1 | F6: 13077.43 | G6: 0 | H6: 31621393
A7: 01-Feb-26 | B7: JV-26-02-0022 | C7: ฺBeginning Stock NBR Latex and Chemical of Plant 1 on Feb'26 | D7: Beginning Stock Compound latex in Dipping lines of Feb'26 | E7: Compounding P1 | F7: 56227.98 | G7: 0 | H7: 31677621
A8: 01-Feb-26 | B8: JV-26-02-0022 | C8: ฺBeginning Stock NBR Latex and Chemical of Plant 1 on Feb'26 | D8: Beginning Stock Compound latex in Dipping lines of Feb'26 | E8: Production P1 | F8: 2879.21 | G8: 0 | H8: 31680500
A9: 01-Feb-26 | B9: JV-26-02-0022 | C9: ฺBeginning Stock NBR Latex and Chemical of Plant 1 on Feb'26 | D9: Beginning Stock Chemical in Production Feb'26 | E9: Production P1 | F9: 14312.4 | G9: 0 | H9: 31694813
A10: 02-Feb-26 | B10: MIJ-26-02-0007 | C10: MI-26-02-0007 | D10: NITRIC ACID 68% (280 KGS/DRUM ),TEXKLEEN P22 (225KG/DRUM)(ALKALINE CLEANER ) | E10: Production P1 | F10: 34020 | G10: 0 | H10: 31728833
A11: 06-Feb-26 | B11: MIJ-26-02-0150 | C11: MI-26-02-0164 | D11: NITRIC ACID 68% (280 KGS/DRUM ),TEXKLEEN P22 (225KG/DRUM)(ALKALINE CLEANER ) | E11: Production P1 | F11: 24570 | G11: 0 | H11: 31753403
A12: 10-Feb-26 | B12: MIJ-26-02-0218 | C12: MI-26-02-0237 | D12: TEXKLEEN P22 (225KG/DRUM)(ALKALINE CLEANER ) | E12: Production P1 | F12: 9450 | G12: 0 | H12: 31762853
A13: 12-Feb-26 | B13: MIJ-26-02-0284 | C13: MI-26-02-0325 | D13: TEXKLEEN P22 (225KG/DRUM)(ALKALINE CLEANER ) | E13: Production P1 | F13: 9450 | G13: 0 | H13: 31772303
A14: 13-Feb-26 | B14: MIJ-26-02-0294 | C14: MI-26-02-0336 | D14: TEXKLEEN P22 (225KG/DRUM)(ALKALINE CLEANER ),TEXKLEEN P22 (225KG/DRUM)(ALKALINE CLEANER ) | E14: Production P1 | F14: 18900 | G14: 0 | H14: 31791203
A15: 17-Feb-26 | B15: MIJ-26-02-0361 | C15: MI-26-02-0408 | D15: NITRIC ACID 68% (280 KGS/DRUM ),TEXKLEEN P22 (225KG/DRUM)(ALKALINE CLEANER ) | E15: Production P1 | F15: 24570 | G15: 0 | H15: 31815773
... A32: 28-Feb-26 | B32: JV-26-02-0131 | C32: Transfer Compound latex and Dispersion between plants of Feb'26 | D32: Transfer Dispersion between plants of Feb'26 | E32: Compounding P1 | F32: 13570.93 | G32: 0 | H32: 34049065
E33: Total | F33: 3380102.9 | G33: 741946.35
E34: Grand Total | F34: 3380102.9 | G34: 741946.35
A35: Printed by Siriporn Boonrath On 11-Mar-2026 09:45:09 AM | B35: Page -1 of 1
E38: Total | F38: 3380102.9 | G38: 741946.35

Sheet CHE-last month
A1: Net consumed Latex and Chemical on Apr'26 | K1: Net consumed Latex and Chemical on Apr'26
B3: Description | D3: Mar'26 | M3: Closing stock
A4: Code | C4: Kgs | D4: Cost : Kg | E4: Value (Bht) | K4: Code | L4: Description | M4: Kgs | N4: Cost : Kg | O4: Value (Bht)
A5: =+K5 -> CH101 | B5: =+L5 -> CHLORINE 99.5% (1,000 KGS CYLINDER) MOITURE 100 MG/KG MAX. | C5: =SUMIF(K:K,A5,M:M) -> 0 | D5: =IF(C5=0,0,E5/C5) -> 0 | E5: =SUMIF($K:$K,A5,O:O) -> 0 | K5: CH101 | L5: CHLORINE 99.5% (1,000 KGS CYLINDER) MOITURE 100 MG/KG MAX. | M5: 0 | N5: 0 | O5: 0
A6: =+K6 -> CH102 | B6: =+L6 -> SODIUM HYDROXIDE 50% (1500 KGS/IBC) | C6: =SUMIF(K:K,A6,M:M) -> 0 | D6: =IF(C6=0,0,E6/C6) -> 0 | E6: =SUMIF($K:$K,A6,O:O) -> 0 | K6: CH102 | L6: SODIUM HYDROXIDE 50% (1500 KGS/IBC) | M6: 0 | N6: 0 | O6: 0
A7: =+K7 -> CH104 | B7: =+L7 -> SPECLEAN 11 (246 KGS /DRUM) | C7: =SUMIF(K:K,A7,M:M) -> 0 | D7: =IF(C7=0,0,E7/C7) -> 0 | E7: =SUMIF($K:$K,A7,O:O) -> 0 | K7: CH104 | L7: SPECLEAN 11 (246 KGS /DRUM) | M7: 0 | N7: 0 | O7: 0
A8: =+K8 -> CH105 | B8: =+L8 -> HISOL D203 (QA75/137) 200 KGS/DRUM (MOQ 400KG/TRIP) | C8: =SUMIF(K:K,A8,M:M) -> 0 | D8: =IF(C8=0,0,E8/C8) -> 0 | E8: =SUMIF($K:$K,A8,O:O) -> 0 | K8: CH105 | L8: HISOL D203 (QA75/137) 200 KGS/DRUM (MOQ 400KG/TRIP) | M8: 0 | N8: 0 | O8: 0
A9: =+K9 -> CH106 | B9: =+L9 -> OCTOSOL 643 (200KG/DRUM) | C9: =SUMIF(K:K,A9,M:M) -> 24.103642 | D9: =IF(C9=0,0,E9/C9) -> 25.550081 | E9: =SUMIF($K:$K,A9,O:O) -> 615.85 | K9: CH106 | L9: OCTOSOL 643 (200KG/DRUM) | M9: 24.103642 | N9: 25.550081 | O9: 615.85
A10: =+K10 -> CH109 | B10: =+L10 -> VIVASHIELD 9177 WAX (950KG/IBC) | C10: =SUMIF(K:K,A10,M:M) -> 0 | D10: =IF(C10=0,0,E10/C10) -> 0 | E10: =SUMIF($K:$K,A10,O:O) -> 0 | K10: CH109 | L10: VIVASHIELD 9177 WAX (950KG/IBC) | M10: 0 | N10: 0 | O10: 0
A11: =+K11 -> CH110 | B11: =+L11 -> CS COAT T403 (1000 KG/TANK) | C11: =SUMIF(K:K,A11,M:M) -> 0 | D11: =IF(C11=0,0,E11/C11) -> 0 | E11: =SUMIF($K:$K,A11,O:O) -> 0 | K11: CH110 | L11: CS COAT T403 (1000 KG/TANK) | M11: 0 | N11: 0 | O11: 0
A12: =+K12 -> CH111 | B12: =+L12 -> ALKALINE CLEAN S4 (1100 KG/TANK) | C12: =SUMIF(K:K,A12,M:M) -> 0 | D12: =IF(C12=0,0,E12/C12) -> 0 | E12: =SUMIF($K:$K,A12,O:O) -> 0 | K12: CH111 | L12: ALKALINE CLEAN S4 (1100 KG/TANK) | M12: 0 | N12: 0 | O12: 0
A13: =+K13 -> CH112 | B13: =+L13 -> TRUCOAT NR 12 (200KG/DRUM) MOQ=16,000KG/TRIP | C13: =SUMIF(K:K,A13,M:M) -> 0 | D13: =IF(C13=0,0,E13/C13) -> 0 | E13: =SUMIF($K:$K,A13,O:O) -> 0 | K13: CH112 | L13: TRUCOAT NR 12 (200KG/DRUM) MOQ=16,000KG/TRIP | M13: 0 | N13: 0 | O13: 0
A14: =+K14 -> CH113 | B14: =+L14 -> CALCIUM NITRATE LIQUOR 54- 56% (300KG/DRUM)-MEYCHERN | C14: =SUMIF(K:K,A14,M:M) -> 0 | D14: =IF(C14=0,0,E14/C14) -> 0 | E14: =SUMIF($K:$K,A14,O:O) -> 0 | K14: CH113 | L14: CALCIUM NITRATE LIQUOR 54- 56% (300KG/DRUM)-MEYCHERN | M14: 0 | N14: 0 | O14: 0
A15: =+K15 -> CH114 | B15: =+L15 -> TRANSCURE ZDB50 (225KG/DRUM) | C15: =SUMIF(K:K,A15,M:M) -> 0 | D15: =IF(C15=0,0,E15/C15) -> 0 | E15: =SUMIF($K:$K,A15,O:O) -> 0 | K15: CH114 | L15: TRANSCURE ZDB50 (225KG/DRUM) | M15: 0 | N15: 0 | O15: 0
A16: =+K16 -> CH115 | B16: =+L16 -> TRANSACT ZNO60 (250KG/DRUM) | C16: =SUMIF(K:K,A16,M:M) -> 0 | D16: =IF(C16=0,0,E16/C16) -> 0 | E16: =SUMIF($K:$K,A16,O:O) -> 0 | K16: CH115 | L16: TRANSACT ZNO60 (250KG/DRUM) | M16: 0 | N16: 0 | O16: 0
... A169: =+K169 -> SFG-Water | B169: =+L169 -> Water | C169: =SUMIF(K:K,A169,M:M) -> 44115.782 | D169: =IF(C169=0,0,E169/C169) -> 0 | E169: =SUMIF($K:$K,A169,O:O) -> 0 | K169: SFG-Water | L169: Water | M169: 44115.782 | N169: 0 | O169: 0
C170: =SUM(C6:C168)-C168 -> 35845.211 | E170: =SUM(E6:H167) -> 541750.3 | M170: =SUM(M6:M168)-M168 -> 35845.211 | O170: =SUM(O6:O168) -> 541750.3
A172: LN01 | B172: NITRILE LATEX | C172: =SUMIF(K:K,A172,M:M) -> 42708.388 | D172: =IF(C172=0,0,E172/C172) -> 43.988122 | E172: =SUMIF($K:$K,A172,O:O) -> 1878661.8 | K172: LN01 | L172: NITRILE LATEX | M172: 42708.388 | N172: 43.988122 | O172: 1878661.8
B173: **check Total LN01 with Detail as below** | D173: =IF(C173=0,0,E173/C173) -> 0 | L173: **check Total LN01 with Detail as below**
A174: NBR01 | B174: SYNTHETIC LATEX BST NBL 8503S | C174: =M174 -> 42708.388 | D174: =N174 -> 43.988122 | E174: =O174 -> 1878661.8 | K174: NBR01 | L174: SYNTHETIC LATEX BST NBL 8503S | M174: 42708.388 | N174: 43.988122 | O174: 1878661.8
A175: NBR11 | B175: NBR LATEX KNL830 | C175: =M175 -> 0 | D175: =N175 -> 0 | E175: =O175 -> 0 | K175: NBR13 | L175: SYNTHOMER 6329 | M175: 0 | N175: 0 | O175: 0
A176: NBR13 | B176: SYNTHOMER 6329 | C176: =M176 -> 0 | D176: =N176 -> 0 | E176: =O176 -> 0 | K176: NBR30 | L176: (TEST) NBR-XY806
K177: NBR12 | L177: SYNTHETIC LATEX '' LG NITRILE LUTEX 125 ''
C185: =+C172+C170 -> 78553.598 | E185: =+E170+E172 -> 2420412.1 | M185: =+M170+M172 -> 78553.598 | O185: =+O170+O172 -> 2420412.1

Sheet NBR Latex-Store
A1: Mercator Medical (Thailand) LTD.
A2: Stock Card Report By Location- Fin Year Based
A3: From 01-May-26 To 31-May-26 | F3: Costing method: WA | J3: TAX ID : | L3: 0905546002869
A5: Code | B5: Item | C5: UOM | F5: Received Qty | G5: Received Amount | H5: Transfer from Inv Store P1 Qty | I5: Transfer from Inv Store P1 Amount | J5: Transfer from Inv Store P2 Qty | K5: Transfer from Inv Store P2 Amount | L5: Transfer from Inv Store P3 Qty | M5: Transfer from Inv Store P3 Amount | O5: Transfer from Comp P1 Qty | P5: Transfer from Comp P1 Amount | Q5: Transfer from Comp P2 Qty | R5: Transfer from Comp P2 Amount | S5: Transfer from Comp P3 Qty | T5: Transfer from Comp P3 Amount | U5: Transfer from Prod Store P1 Qty | V5: Transfer from Prod Store P1 Amount | W5: Transfer from Prod Store P2 Qty | X5: Transfer from Prod Store P2 Amount | Z5: Transfer from Prod Store P3 Qty | AA5: Transfer from Prod Store P3 Amount | AC5: Issued Qty | AD5: Issued Amount | AE5: Transfer to Inv Store P1 Qty | AF5: Transfer to Inv Store P1 Amount | AG5: Transfer to Inv Store P2 Qty | AH5: Transfer to Inv Store P2 Amount | AI5: Transfer to Inv Store P3 Qty | AJ5: Transfer to Inv Store P3 Amount | AK5: Transfer to Comp P1 Qty | AM5: Transfer to Comp P1 Amount | AN5: Transfer to Comp P2 Qty | AO5: Transfer to Comp P2 Amount | AQ5: Transfer to Comp P3 Qty | AR5: Transfer to Comp P3 Amount | AS5: Transfer to Prod Store P1 Qty | AT5: Transfer to Prod Store P1 Amount | AU5: Transfer to Prod Store P2 Qty | AV5: Transfer to Prod Store P2 Amount | AW5: Transfer to Prod Store P3 Qty | AX5: Transfer to Prod Store P3 Amount | AY5: Adjustment Qty | AZ5: Balance Qty | BA5: Balance Unit Cost | BB5: Balance Amount | BC5: Category
A6: Inv Store - Plant 1
B13: Total | F13: =SUM(F7:F12) -> 0 | G13: =SUM(G7:G12) -> 0 | H13: =SUM(H7:H12) -> 0 | I13: =SUM(I7:I12) -> 0 | J13: =SUM(J7:J12) -> 0 | K13: =SUM(K7:K12) -> 0 | L13: =SUM(L7:L12) -> 0 | M13: =SUM(M7:M12) -> 0 | ... AZ13: =SUM(AZ7:AZ12) -> 0 | BB13: =SUM(BB7:BB12) -> 0
C15: check | AZ15: 0 | BB15: 0
B17: ผลต่างจากใบตาชั่ง

Sheet NBR Latex-Comp
A1: Mercator Medical (Thailand) LTD. | AE1: 0
A2: Stock Card Report By Location- Fin Year Based
A3: From 01-May-26 To 31-May-26 | F3: Costing method: WA | J3: TAX ID : | L3: 0905546002869
A5: Code | B5: Item | C5: UOM | D5: B/F | F5: Received Qty | G5: Received Amount | H5: Transfer from Inv Store P1 Qty | I5: Transfer from Inv Store P1 Amount | J5: Transfer from Inv Store P2 Qty | K5: Transfer from Inv Store P2 Amount | L5: Transfer from Inv Store P3 Qty | M5: Transfer from Inv Store P3 Amount | O5: Transfer from Comp P1 Qty | P5: Transfer from Comp P1 Amount | Q5: Transfer from Comp P2 Qty | R5: Transfer from Comp P2 Amount | S5: Transfer from Comp P3 Qty | T5: Transfer from Comp P3 Amount | U5: Transfer from Prod Store P1 Qty | V5: Transfer from Prod Store P1 Amount | W5: Transfer from Prod Store P2 Qty | X5: Transfer from Prod Store P2 Amount | Z5: Transfer from Prod Store P3 Qty | AA5: Transfer from Prod Store P3 Amount | AC5: Issued Qty | AD5: Issued Amount | AE5: Transfer to Inv Store P1 Qty | AF5: Transfer to Inv Store P1 Amount | AG5: Transfer to Inv Store P2 Qty | AH5: Transfer to Inv Store P2 Amount | AI5: Transfer to Inv Store P3 Qty | AJ5: Transfer to Inv Store P3 Amount | AK5: Transfer to Comp P1 Qty | AM5: Transfer to Comp P1 Amount | AN5: Transfer to Comp P2 Qty | AO5: Transfer to Comp P2 Amount | AQ5: Transfer to Comp P3 Qty | AR5: Transfer to Comp P3 Amount | AS5: Transfer to Prod Store P1 Qty | AT5: Transfer to Prod Store P1 Amount | AU5: Transfer to Prod Store P2 Qty | AV5: Transfer to Prod Store P2 Amount | AW5: Transfer to Prod Store P3 Qty | AX5: Transfer to Prod Store P3 Amount | AY5: Adjustment Qty | AZ5: Balance Qty | BA5: Balance Unit Cost | BB5: Balance Amount | BC5: Category
A6: Compound store - Plant 1 | D6: Qty | E6: Amount
A7: NBR01 | B7: SYNTHETIC LATEX BST NBL 8503S | C7: Kg | D7: 43750 | E7: 2112425 | F7: 0 | G7: 0 | H7: 0 | I7: 0 | J7: 128030 | K7: 6777780.2 | L7: 0 | M7: 0 | O7: 0 | P7: 0 | Q7: 0 | R7: 0 | S7: 0 | T7: 0 | U7: 0 | V7: 0 | W7: 0 | X7: 0 | Z7: 0 | AA7: 0 | AC7: 84083 | AD7: 4247613.7 | AE7: 0 | AF7: 0 | AG7: 0 | AH7: 0 | AI7: 0 | AJ7: 0 | AK7: 0 | AM7: 0 | AN7: 6760 | AO7: 357867.64 | AQ7: 0 | AR7: 0 | AS7: 0 | AT7: 0 | AU7: 0 | AV7: 0 | AW7: 0 | AX7: 0 | AY7: 0 | AZ7: 80937 | BA7: 52.938999 | BB7: 4284723.8 | BC7: NBR-Latex
A8: NBR12 | B8: SYNTHETIC LATEX '' LG NITRILE LUTEX 125 '' | C8: Kg | D8: 144908 | E8: 3332719.8 | F8: 0 | G8: 0 | H8: 0 | I8: 0 | J8: 0 | K8: 0 | L8: 0 | M8: 0 | O8: 0 | P8: 0 | Q8: 0 | R8: 0 | S8: 0 | T8: 0 | U8: 0 | V8: 0 | W8: 0 | X8: 0 | Z8: 0 | AA8: 0 | AC8: 0 | AD8: 0 | AE8: 0 | AF8: 0 | AG8: 0 | AH8: 0 | AI8: 0 | AJ8: 0 | AK8: 0 | AM8: 0 | AN8: 0 | AO8: 0 | AQ8: 29879 | AR8: 691743.98 | AS8: 0 | AT8: 0 | AU8: 0 | AV8: 0 | AW8: 0 | AX8: 0 | AY8: 0 | AZ8: 115029 | BA8: 22.959217 | BB8: 2640975.8 | BC8: NBR-Latex
A9: NBR30 | B9: (TEST) NBR-XY806 | C9: Kg | D9: 87900 | E9: 2815557.1 | F9: 0 | G9: 0 | H9: 0 | I9: 0 | J9: 0 | K9: 0 | L9: 109760 | M9: 4724320.9 | O9: 0 | P9: 0 | Q9: 25945 | R9: 1034216.1 | S9: 14671 | T9: 468421.56 | U9: 0 | V9: 0 | W9: 0 | X9: 0 | Z9: 0 | AA9: 0 | AC9: 220715 | AD9: 8455174.4 | AE9: 0 | AF9: 0 | AG9: 0 | AH9: 0 | AI9: 0 | AJ9: 0 | AK9: 0 | AM9: 0 | AN9: 14000 | AO9: 450427.6 | AQ9: 0 | AR9: 0 | AS9: 0 | AT9: 0 | AU9: 0 | AV9: 0 | AW9: 0 | AX9: 0 | AY9: 0 | AZ9: 3561 | BA9: 38.44813 | BB9: 136913.79 | BC9: NBR-Latex
A10: NBR31 | B10: (TEST) NBR LATEX, RFA-7632 | C10: Kg | D10: 0 | E10: 0 | F10: 0 | G10: 0 | H10: 0 | I10: 0 | J10: 0 | K10: 0 | L10: 45950 | M10: 2080514.9 | O10: 0 | P10: 0 | Q10: 10000 | R10: 397354 | S10: 0 | T10: 0 | U10: 0 | V10: 0 | W10: 0 | X10: 0 | Z10: 0 | AA10: 0 | AC10: 8377 | AD10: 379292.13 | AE10: 0 | AF10: 0 | AG10: 0 | AH10: 0 | AI10: 0 | AJ10: 0 | AK10: 0 | AM10: 0 | AN10: 10000 | AO10: 397354 | AQ10: 0 | AR10: 0 | AS10: 0 | AT10: 0 | AU10: 0 | AV10: 0 | AW10: 0 | AX10: 0 | AY10: 0 | AZ10: 37573 | BA10: 45.2778 | BB10: 1701222.8 | BC10: NBR-Latex
B13: Total | D13: =SUM(D7:D12) -> 276558 | E13: =SUM(E7:E12) -> 8260701.9 | F13: =SUM(F7:F12) -> 0 | G13: =SUM(G7:G12) -> 0 | H13: =SUM(H7:H12) -> 0 | I13: =SUM(I7:I12) -> 0 | J13: =SUM(J7:J12) -> 128030 | K13: =SUM(K7:K12) -> 6777780.2 | ... AZ13: =SUM(AZ7:AZ12) -> 237100 | BB13: =SUM(BB7:BB12) -> 8763836.2
C15: check | D15: 276558 | E15: 8260701.9 | AZ15: =+D13+F13+J13+L13+Q13+S13-AC13-AN13-AQ13 -> 237100 | BB15: =+E13+K13+M13+T13-AD13-AO13-AR13+G13+R13 -> 8763836.2
AZ16: =+AZ13-AZ15 -> 0 | BB16: =+BB13-BB15 -> 0
C17: in | D17: =F13+J13+L13+Q13+S13 -> 334356
C18: out | D18: =AC13+AN13+AQ13 -> 373814
C19: BL | D19: =D13+D17-D18 -> 237100

Sheet Che-Store
A1: Mercator Medical (Thailand) LTD.
A2: Stock Card Report By Location- Fin Year Based
A3: From 01-May-26 To 31-May-26 | F3: Costing method: WA | J3: TAX ID : | L3: 0905546002869
A5: Code | B5: Item | C5: UOM | D5: B/F | F5: Received Qty | G5: Received Amount | H5: Transfer from Inv Store P1 Qty | I5: Transfer from Inv Store P1 Amount | J5: Transfer from Inv Store P2 Qty | K5: Transfer from Inv Store P2 Amount | L5: Transfer from Inv Store P3 Qty | M5: Transfer from Inv Store P3 Amount | O5: Transfer from Comp P1 Qty | P5: Transfer from Comp P1 Amount | Q5: Transfer from Comp P2 Qty | R5: Transfer from Comp P2 Amount | S5: Transfer from Comp P3 Qty | T5: Transfer from Comp P3 Amount | U5: Transfer from Prod Store P1 Qty | V5: Transfer from Prod Store P1 Amount | W5: Transfer from Prod Store P2 Qty | X5: Transfer from Prod Store P2 Amount | Z5: Transfer from Prod Store P3 Qty | AA5: Transfer from Prod Store P3 Amount | AC5: Issued Qty | AD5: @ | AE5: Issued Amount | AF5: Transfer to Inv Store P1 Qty | AG5: Transfer to Inv Store P1 Amount | AH5: Transfer to Inv Store P2 Qty | AI5: Transfer to Inv Store P2 Amount | AJ5: Transfer to Inv Store P3 Qty | AK5: Transfer to Inv Store P3 Amount | AL5: Transfer to Comp P1 Qty | AN5: Transfer to Comp P1 Amount | AO5: Transfer to Comp P2 Qty | AP5: Transfer to Comp P2 Amount | AR5: Transfer to Comp P3 Qty | AS5: Transfer to Comp P3 Amount | AT5: Transfer to Prod Store P1 Qty | AU5: Transfer to Prod Store P1 Amount | AV5: Transfer to Prod Store P2 Qty | AW5: Transfer to Prod Store P2 Amount | AX5: Transfer to Prod Store P3 Qty | AY5: Transfer to Prod Store P3 Amount | AZ5: Adjustment Qty | BA5: Balance Qty | BB5: Balance Unit Cost | BC5: Balance Amount | BD5: Category
A6: Inv Store - Plant 1 | D6: Qty | E6: Amount
A7: CH145 | B7: BIO-F20 (25KG/PACK) - TNG (BIOCIDE) | C7: Kg | D7: 100 | E7: 13483.19 | F7: 100 | G7: 13709.36 | H7: 0 | I7: 0 | J7: 0 | K7: 0 | L7: 0 | M7: 0 | O7: 0 | P7: 0 | Q7: 0 | R7: 0 | S7: 0 | T7: 0 | U7: 0 | V7: 0 | W7: 0 | X7: 0 | Z7: 0 | AA7: 0 | AC7: 0 | AE7: 0 | AF7: 0 | AG7: 0 | AH7: 0 | AI7: 0 | AJ7: 0 | AK7: 0 | AL7: 75 | AN7: 10112.49 | AO7: 0 | AP7: 0 | AR7: 0 | AS7: 0 | AT7: 0 | AU7: 0 | AV7: 0 | AW7: 0 | AX7: 0 | AY7: 0 | AZ7: 0 | BA7: 125 | BB7: 136.64048 | BC7: 17080.06 | BD7: CHEMICAL
A8: CH196 | B8: TEXKLEEN P22 (225KG/DRUM)(ALKALINE CLEANER ) | C8: Kg | D8: 0 | E8: 0 | F8: 0 | G8: 0 | H8: 0 | I8: 0 | J8: 4500 | K8: 47250 | L8: 0 | M8: 0 | O8: 0 | P8: 0 | Q8: 0 | R8: 0 | S8: 0 | T8: 0 | U8: 0 | V8: 0 | W8: 0 | X8: 0 | Z8: 0 | AA8: 0 | AC8: 4500 | AD8: =+AE8/AC8 -> 10.5 | AE8: 47250 | AF8: 0 | AG8: 0 | AH8: 0 | AI8: 0 | AJ8: 0 | AK8: 0 | AL8: 0 | AN8: 0 | AO8: 0 | AP8: 0 | AR8: 0 | AS8: 0 | AT8: 0 | AU8: 0 | AV8: 0 | AW8: 0 | AX8: 0 | AY8: 0 | AZ8: 0 | BA8: 0 | BB8: 0 | BC8: 0 | BD8: CHEMICAL
A9: CH23 | B9: AMMONIUM HYDROXIDE (180KGS /DRUM)(900KG/IBC) | C9: Kg | D9: 1494 | E9: 24210 | F9: 0 | G9: 0 | H9: 0 | I9: 0 | J9: 0 | K9: 0 | L9: 0 | M9: 0 | O9: 0 | P9: 0 | Q9: 0 | R9: 0 | S9: 0 | T9: 0 | U9: 0 | V9: 0 | W9: 0 | X9: 0 | Z9: 0 | AA9: 0 | AC9: 0 | AE9: 0 | AF9: 0 | AG9: 0 | AH9: 0 | AI9: 0 | AJ9: 0 | AK9: 0 | AL9: 432 | AN9: 6952.5 | AO9: 0 | AP9: 0 | AR9: 0 | AS9: 0 | AT9: 0 | AU9: 0 | AV9: 0 | AW9: 0 | AX9: 0 | AY9: 0 | AZ9: 0 | BA9: 1062 | BB9: 16.25 | BC9: 17257.5 | BD9: CHEMICAL
A10: CH233 | B10: MAXSILK B280M(1000KG/IBC) - NBR POLYMER | C10: Kg | D10: 17000 | E10: 1074284.1 | F10: 19000 | G10: 1290101.9 | H10: 0 | I10: 0 | J10: 0 | K10: 0 | L10: 0 | M10: 0 | O10: 0 | P10: 0 | Q10: 0 | R10: 0 | S10: 0 | T10: 0 | U10: 0 | V10: 0 | W10: 0 | X10: 0 | Z10: 0 | AA10: 0 | AC10: 0 | AE10: 0 | AF10: 0 | AG10: 0 | AH10: 0 | AI10: 0 | AJ10: 0 | AK10: 0 | AL10: 12000 | AN10: 757195.4 | AO10: 0 | AP10: 0 | AR10: 0 | AS10: 0 | AT10: 0 | AU10: 0 | AV10: 0 | AW10: 0 | AX10: 0 | AY10: 0 | AZ10: 0 | BA10: 24000 | BB10: 66.966275 | BC10: 1607190.6 | BD10: CHEMICAL
A11: CH245 | B11: (TEST) SPECLEAN 10 (230KG/DRUM) - ALKALINE CLEANER | C11: Kg | D11: 0 | E11: 0 | F11: 0 | G11: 0 | H11: 0 | I11: 0 | J11: 8280 | K11: 79290.56 | L11: 0 | M11: 0 | O11: 0 | P11: 0 | Q11: 0 | R11: 0 | S11: 0 | T11: 0 | U11: 0 | V11: 0 | W11: 0 | X11: 0 | Z11: 0 | AA11: 0 | AC11: 8280 | AD11: =+AE11/AC11 -> 9.5761546 | AE11: 79290.56 | AF11: 0 | AG11: 0 | AH11: 0 | AI11: 0 | AJ11: 0 | AK11: 0 | AL11: 0 | AN11: 0 | AO11: 0 | AP11: 0 | AR11: 0 | AS11: 0 | AT11: 0 | AU11: 0 | AV11: 0 | AW11: 0 | AX11: 0 | AY11: 0 | AZ11: 0 | BA11: 0 | BB11: 0 | BC11: 0 | BD11: CHEMICAL
A12: CH252 | B12: (TEST) KLEEN S21 (225KG/DRUM) (ALAKLINE CLEANNER) | C12: Kg | D12: 0 | E12: 0 | F12: 0 | G12: 0 | H12: 0 | I12: 0 | J12: 900 | K12: 8550 | L12: 0 | M12: 0 | O12: 0 | P12: 0 | Q12: 0 | R12: 0 | S12: 0 | T12: 0 | U12: 0 | V12: 0 | W12: 0 | X12: 0 | Z12: 0 | AA12: 0 | AC12: 900 | AD12: =+AE12/AC12 -> 9.5 | AE12: 8550 | AF12: 0 | AG12: 0 | AH12: 0 | AI12: 0 | AJ12: 0 | AK12: 0 | AL12: 0 | AN12: 0 | AO12: 0 | AP12: 0 | AR12: 0 | AS12: 0 | AT12: 0 | AU12: 0 | AV12: 0 | AW12: 0 | AX12: 0 | AY12: 0 | AZ12: 0 | BA12: 0 | BB12: 0 | BC12: 0 | BD12: CHEMICAL
A13: CH26 | B13: NITRIC ACID 68% (280 KGS/DRUM ) | C13: Kg | D13: 0 | E13: 0 | F13: 0 | G13: 0 | H13: 0 | I13: 0 | J13: 3360 | K13: 52080 | L13: 0 | M13: 0 | O13: 0 | P13: 0 | Q13: 0 | R13: 0 | S13: 0 | T13: 0 | U13: 0 | V13: 0 | W13: 0 | X13: 0 | Z13: 0 | AA13: 0 | AC13: 3360 | AD13: =+AE13/AC13 -> 15.5 | AE13: 52080 | AF13: 0 | AG13: 0 | AH13: 0 | AI13: 0 | AJ13: 0 | AK13: 0 | AL13: 0 | AN13: 0 | AO13: 0 | AP13: 0 | AR13: 0 | AS13: 0 | AT13: 0 | AU13: 0 | AV13: 0 | AW13: 0 | AX13: 0 | AY13: 0 | AZ13: 0 | BA13: 0 | BB13: 0 | BC13: 0 | BD13: CHEMICAL
B14: Total | D14: =SUM(D7:D13) -> 18594 | E14: =SUM(E7:E13) -> 1111977.3 | F14: =SUM(F7:F13) -> 19100 | G14: =SUM(G7:G13) -> 1303811.3 | J14: =SUM(J7:J13) -> 17040 | K14: =SUM(K7:K13) -> 187170.56 | L14: =SUM(L7:L13) -> 0 | M14: =SUM(M7:M13) -> 0 | N14: =SUM(N7:N13) -> 0 | O14: =SUM(O7:O13) -> 0 | P14: =SUM(P7:P13) -> 0 | Q14: =SUM(Q7:Q13) -> 0 | ... AC14: =SUM(AC7:AC13) -> 17040 | AE14: =SUM(AE7:AE13) -> 187170.56 | AF14: =SUM(AF7:AF13) -> 0 | AG14: =SUM(AG7:AG13) -> 0 | AH14: =SUM(AH7:AH13) -> 0 | AI14: =SUM(AI7:AI13) -> 0 | AJ14: =SUM(AJ7:AJ13) -> 0 | AK14: =SUM(AK7:AK13) -> 0 | AL14: =SUM(AL7:AL13) -> 12507 | ... BA14: =SUM(BA7:BA13) -> 25187 | BC14: =SUM(BC7:BC13) -> 1641528.2
C16: check | D16: 18594 | E16: 1111977.3 | G16: ='1008-402'!F38 -> 1303811.2 | BA16: =+D14+F14+J14-AC14-AH14-AJ14-AL14+L14 -> 25187 | BC16: =+E14+G14+K14-AE14-AI14-AK14-AN14+M14 -> 1641528.2
G17: =+G14-G16 -> 0.09

Sheet Che-Comp
A1: Mercator Medical (Thailand) LTD.
A2: Stock Card Report By Location- Fin Year Based
A3: From 01-May-26 To 31-May-26 | F3: Costing method: WA | J3: TAX ID : | L3: 0905546002869
A5: Code | B5: Item | C5: UOM | D5: B/F | F5: Received Qty | G5: Received Amount | H5: Transfer from Inv Store P1 Qty | I5: Transfer from Inv Store P1 Amount | J5: Transfer from Inv Store P2 Qty | K5: Transfer from Inv Store P2 Amount | L5: Transfer from Inv Store P3 Qty | M5: Transfer from Inv Store P3 Amount | O5: Transfer from Comp P1 Qty | P5: Transfer from Comp P1 Amount | Q5: Transfer from Comp P2 Qty | R5: Transfer from Comp P2 Amount | S5: Transfer from Comp P3 Qty | T5: Transfer from Comp P3 Amount | U5: Transfer from Prod Store P1 Qty | V5: Transfer from Prod Store P1 Amount | W5: Transfer from Prod Store P2 Qty | X5: Transfer from Prod Store P2 Amount | Z5: Transfer from Prod Store P3 Qty | AA5: Transfer from Prod Store P3 Amount | AC5: Issued Qty | AE5: Issued Amount | AF5: Transfer to Inv Store P1 Qty | AG5: Transfer to Inv Store P1 Amount | AH5: Transfer to Inv Store P2 Qty | AI5: Transfer to Inv Store P2 Amount | AJ5: Transfer to Inv Store P3 Qty | AK5: Transfer to Inv Store P3 Amount | AL5: Transfer to Comp P1 Qty | AN5: Transfer to Comp P1 Amount | AO5: Transfer to Comp P2 Qty | AP5: Transfer to Comp P2 Amount | AR5: Transfer to Comp P3 Qty | AS5: Transfer to Comp P3 Amount | AT5: Transfer to Prod Store P1 Qty | AU5: Transfer to Prod Store P1 Amount | AV5: Transfer to Prod Store P2 Qty | AW5: Transfer to Prod Store P2 Amount | AX5: Transfer to Prod Store P3 Qty | AY5: Transfer to Prod Store P3 Amount | AZ5: Adjustment Qty | BA5: Balance Qty | BB5: Balance Unit Cost | BC5: Balance Amount | BD5: Category
A6: Compound store - Plant 1 | D6: QTY | E6: Amount
A7: CH106 | B7: OCTOSOL 643 (1000KG/IBC)(SDBS) | C7: Kg | D7: 0 | E7: 0 | F7: 0 | G7: 0 | H7: 0 | I7: 0 | J7: 1000 | K7: 32574.8 | L7: 0 | M7: 0 | O7: 0 | P7: 0 | Q7: 0 | R7: 0 | S7: 0 | T7: 0 | U7: 0 | V7: 0 | W7: 0 | X7: 0 | Z7: 0 | AA7: 0 | AC7: 20.15 | AD7: =+AE7/AC7 -> 32.57469 | AE7: 656.38 | AF7: 0 | AG7: 0 | AH7: 0 | AI7: 0 | AJ7: 0 | AK7: 0 | AL7: 0 | AN7: 0 | AO7: 0 | AP7: 0 | AR7: 0 | AS7: 0 | AT7: 0 | AU7: 0 | AV7: 0 | AW7: 0 | AX7: 0 | AY7: 0 | AZ7: 0 | BA7: 979.85 | BB7: 32.574802 | BC7: 31918.42 | BD7: CHEMICAL
A8: CH128 | B8: FARSPERSE BLUE MPL1523 (20 KGS/PAIL) (PIGMENT) | C8: Kg | D8: 126.35 | E8: 27335.85 | F8: 0 | G8: 0 | H8: 0 | I8: 0 | J8: 0 | K8: 0 | L8: 0 | M8: 0 | O8: 0 | P8: 0 | Q8: 0 | R8: 0 | S8: 0 | T8: 0 | U8: 0 | V8: 0 | W8: 0 | X8: 0 | Z8: 0 | AA8: 0 | AC8: 77.74 | AD8: =+AE8/AC8 -> 216.34127 | AE8: 16818.37 | AF8: 0 | AG8: 0 | AH8: 0 | AI8: 0 | AJ8: 0 | AK8: 0 | AL8: 0 | AN8: 0 | AO8: 48.61 | AP8: 10517.49 | AR8: 0 | AS8: 0 | AT8: 0 | AU8: 0 | AV8: 0 | AW8: 0 | AX8: 0 | AY8: 0 | AZ8: 0 | BA8: 0 | BB8: 0 | BC8: 0 | BD8: CHEMICAL
A9: CH140 | B9: HYDROTINT BLACK BA (20KG/PK) PIGMENT | C9: Kg | D9: 240 | E9: 13880.94 | F9: 0 | G9: 0 | H9: 0 | I9: 0 | J9: 2200 | K9: 128490.39 | L9: 0 | M9: 0 | O9: 0 | P9: 0 | Q9: 100 | R9: 5748.23 | S9: 0 | T9: 0 | U9: 0 | V9: 0 | W9: 0 | X9: 0 | Z9: 0 | AA9: 0 | AC9: 2090 | AD9: =+AE9/AC9 -> 57.918555 | AE9: 121049.78 | AF9: 0 | AG9: 0 | AH9: 0 | AI9: 0 | AJ9: 0 | AK9: 0 | AL9: 0 | AN9: 0 | AO9: 0 | AP9: 0 | AR9: 0 | AS9: 0 | AT9: 0 | AU9: 0 | AV9: 0 | AW9: 0 | AX9: 0 | AY9: 0 | AZ9: 0 | BA9: 450 | BB9: 60.154799 | BC9: 27069.78 | BD9: CHEMICAL
A10: CH145 | B10: BIO-F20 (25KG/PACK) - TNG (BIOCIDE) | C10: Kg | D10: 80 | E10: 10784.77 | F10: 5.8 | G10: 781.78 | H10: 75 | I10: 10112.49 | J10: 0 | K10: 0 | L10: 0 | M10: 0 | O10: 0 | P10: 0 | Q10: 0 | R10: 0 | S10: 0 | T10: 0 | U10: 0 | V10: 0 | W10: 0 | X10: 0 | Z10: 0 | AA10: 0 | AC10: 108.8 | AD10: =+AE10/AC10 -> 134.83382 | AE10: 14669.92 | AF10: 0 | AG10: 0 | AH10: 0 | AI10: 0 | AJ10: 0 | AK10: 0 | AL10: 0 | AN10: 0 | AO10: 0 | AP10: 0 | AR10: 0 | AS10: 0 | AT10: 0 | AU10: 0 | AV10: 0 | AW10: 0 | AX10: 0 | AY10: 0 | AZ10: 0 | BA10: 52 | BB10: 134.79077 | BC10: 7009.12 | BD10: CHEMICAL
A11: CH168 | B11: ALPHALINK 30 (ACELERATOR FREE CROSSLINKER) (1100KG/IBC) | C11: Kg | D11: 0 | E11: 0 | F11: 0 | G11: 0 | H11: 0 | I11: 0 | J11: 3300 | K11: 192734.85 | L11: 0 | M11: 0 | O11: 0 | P11: 0 | Q11: 0 | R11: 0 | S11: 0 | T11: 0 | U11: 0 | V11: 0 | W11: 0 | X11: 0 | Z11: 0 | AA11: 0 | AC11: 1170.96 | AD11: =+AE11/AC11 -> 58.404506 | AE11: 68389.34 | AF11: 0 | AG11: 0 | AH11: 0 | AI11: 0 | AJ11: 0 | AK11: 0 | AL11: 0 | AN11: 0 | AO11: 1100 | AP11: 64244.95 | AR11: 0 | AS11: 0 | AT11: 0 | AU11: 0 | AV11: 0 | AW11: 0 | AX11: 0 | AY11: 0 | AZ11: 0 | BA11: 1029.04 | BB11: 58.404494 | BC11: 60100.56 | BD11: CHEMICAL
A12: CH211 | B12: CALCIUM NITRATE TETRAHYDRATE CRYSTAL ( CALCIUM SALT )(25KG/BG) | C12: Kg | D12: 9000 | E12: 74622.63 | F12: 0 | G12: 0 | H12: 0 | I12: 0 | J12: 112500 | K12: 948304.5 | L12: 0 | M12: 0 | O12: 0 | P12: 0 | Q12: 0 | R12: 0 | S12: 0 | T12: 0 | U12: 0 | V12: 0 | W12: 0 | X12: 0 | Z12: 0 | AA12: 0 | AC12: 120040 | AD12: =+AE12/AC12 -> 8.4181774 | AE12: 1010518 | AF12: 0 | AG12: 0 | AH12: 0 | AI12: 0 | AJ12: 0 | AK12: 0 | AL12: 0 | AN12: 0 | AO12: 0 | AP12: 0 | AR12: 0 | AS12: 0 | AT12: 0 | AU12: 0 | AV12: 0 | AW12: 0 | AX12: 0 | AY12: 0 | AZ12: 0 | BA12: 1460 | BB12: 8.4994032 | BC12: 12409.11 | BD12: CHEMICAL
A13: CH212 | B13: POTASSIUM HYDROXIDE FLAKE 90% ( KOH ) ( 25 KGS / BAG )MOQ20000KG/TRIP | C13: Kg | D13: 800 | E13: 28000.04 | F13: 0 | G13: 0 | H13: 0 | I13: 0 | J13: 2100 | K13: 59916.78 | L13: 0 | M13: 0 | O13: 0 | P13: 0 | Q13: 0 | R13: 0 | S13: 0 | T13: 0 | U13: 0 | V13: 0 | W13: 0 | X13: 0 | Z13: 0 | AA13: 0 | AC13: 2400 | AD13: =+AE13/AC13 -> 32.035421 | AE13: 76885.01 | AF13: 0 | AG13: 0 | AH13: 0 | AI13: 0 | AJ13: 0 | AK13: 0 | AL13: 0 | AN13: 0 | AO13: 0 | AP13: 0 | AR13: 0 | AS13: 0 | AT13: 0 | AU13: 0 | AV13: 0 | AW13: 0 | AX13: 0 | AY13: 0 | AZ13: 0 | BA13: 500 | BB13: 22.06351 | BC13: 11031.81 | BD13: CHEMICAL
A14: CH215 | B14: ACUMIN H65 (1600KG/IBC) - EXTENDER | C14: Kg | D14: 7661 | E14: 158257.73 | F14: 0 | G14: 0 | H14: 0 | I14: 0 | J14: 17600 | K14: 365680.64 | L14: 0 | M14: 0 | O14: 0 | P14: 0 | Q14: 0 | R14: 0 | S14: 0 | T14: 0 | U14: 0 | V14: 0 | W14: 0 | X14: 0 | Z14: 0 | AA14: 0 | AC14: 21250 | AD14: =+AE14/AC14 -> 20.738312 | AE14: 440689.13 | AF14: 0 | AG14: 0 | AH14: 0 | AI14: 0 | AJ14: 0 | AK14: 0 | AL14: 0 | AN14: 0 | AO14: 0 | AP14: 0 | AR14: 0 | AS14: 0 | AT14: 0 | AU14: 0 | AV14: 0 | AW14: 0 | AX14: 0 | AY14: 0 | AZ14: 0 | BA14: 4011 | BB14: 20.755189 | BC14: 83249.16 | BD14: CHEMICAL
A15: CH222 | B15: AQUAWAX 022S (950KG/IBC) -WAX | C15: Kg | D15: 1471 | E15: 59113.39 | F15: 0 | G15: 0 | H15: 0 | I15: 0 | J15: 2850 | K15: 125729.46 | L15: 0 | M15: 0 | O15: 0 | P15: 0 | Q15: 0 | R15: 0 | S15: 0 | T15: 0 | U15: 0 | V15: 0 | W15: 0 | X15: 0 | Z15: 0 | AA15: 0 | AC15: 3259 | AD15: =+AE15/AC15 -> 42.341881 | AE15: 137992.19 | AF15: 0 | AG15: 0 | AH15: 0 | AI15: 0 | AJ15: 0 | AK15: 0 | AL15: 0 | AN15: 0 | AO15: 0 | AP15: 0 | AR15: 0 | AS15: 0 | AT15: 0 | AU15: 0 | AV15: 0 | AW15: 0 | AX15: 0 | AY15: 0 | AZ15: 0 | BA15: 1062 | BB15: 44.115499 | BC15: 46850.66 | BD15: CHEMICAL
A16: CH227 | B16: NEOPELEX G-15P (1000KG/IBC) (SDBS) | C16: Kg | D16: 1054.28 | E16: 14759.8 | F16: 0 | G16: 0 | H16: 0 | I16: 0 | J16: 0 | K16: 0 | L16: 1000 | M16: 14000 | O16: 0 | P16: 0 | Q16: 601.2 | R16: 8517.1 | S16: 0 | T16: 0 | U16: 0 | V16: 0 | W16: 0 | X16: 0 | Z16: 0 | AA16: 0 | AC16: 1855.48 | AD16: =+AE16/AC16 -> 14.05404 | AE16: 26076.99 | AF16: 0 | AG16: 0 | AH16: 0 | AI16: 0 | AJ16: 0 | AK16: 0 | AL16: 0 | AN16: 0 | AO16: 800 | AP16: 11200 | AR16: 0 | AS16: 0 | AT16: 0 | AU16: 0 | AV16: 0 | AW16: 0 | AX16: 0 | AY16: 0 | AZ16: 0 | BA16: 0 | BB16: 0 | BC16: 0 | BD16: CHEMICAL
A17: CH23 | B17: AMMONIUM HYDROXIDE (180KGS /DRUM)(900KG/IBC) | C17: Kg | D17: 108 | E17: 1619.36 | F17: 0 | G17: 0 | H17: 432 | I17: 6952.5 | J17: 0 | K17: 0 | L17: 0 | M17: 0 | O17: 0 | P17: 0 | Q17: 0 | R17: 0 | S17: 0 | T17: 0 | U17: 0 | V17: 0 | W17: 0 | X17: 0 | Z17: 0 | AA17: 0 | AC17: 492.8 | AD17: =+AE17/AC17 -> 15.839083 | AE17: 7805.5 | AF17: 0 | AG17: 0 | AH17: 0 | AI17: 0 | AJ17: 0 | AK17: 0 | AL17: 0 | AN17: 0 | AO17: 0 | AP17: 0 | AR17: 0 | AS17: 0 | AT17: 0 | AU17: 0 | AV17: 0 | AW17: 0 | AX17: 0 | AY17: 0 | AZ17: 0 | BA17: 47.2 | BB17: 16.236269 | BC17: 766.36 | BD17: CHEMICAL
A18: CH233 | B18: MAXSILK B280M(1000KG/IBC) - NBR POLYMER | C18: Kg | D18: 2000 | E18: 123017.93 | F18: 0 | G18: 0 | H18: 12000 | I18: 757195 | J18: 0 | K18: 0 | L18: 0 | M18: 0 | O18: 0 | P18: 0 | Q18: 0 | R18: 0 | S18: 0 | T18: 0 | U18: 0 | V18: 0 | W18: 0 | X18: 0 | Z18: 0 | AA18: 0 | AC18: 12494.7 | AD18: =+AE18/AC18 -> 62.807468 | AE18: 784760.47 | AF18: 0 | AG18: 0 | AH18: 0 | AI18: 0 | AJ18: 0 | AK18: 0 | AL18: 0 | AN18: 0 | AO18: 0 | AP18: 0 | AR18: 0 | AS18: 0 | AT18: 0 | AU18: 0 | AV18: 0 | AW18: 0 | AX18: 0 | AY18: 0 | AZ18: 0 | BA18: 1505.3 | BB18: 63.410921 | BC18: 95452.46 | BD18: CHEMICAL
... A20: CH240 | B20: ALPHALINK 50 (200KG/DRUM),(1100KG/IBC) - ACELERATOR FREE CROSSLINKER | C20: Kg | D20: 767 | E20: 59550.23 | F20: 0 | G20: 0 | H20: 0 | I20: 0 | J20: 1100 | K20: 88234.3 | L20: 0 | M20: 0 | O20: 0 | P20: 0 | Q20: 0 | R20: 0 | S20: 0 | T20: 0 | U20: 0 | V20: 0 | W20: 0 | X20: 0 | Z20: 0 | AA20: 0 | AC20: 407.34 | AD20: =+AE20/AC20 -> 77.639859 | AE20: 31625.82 | AF20: 0 | AG20: 0 | AH20: 0 | AI20: 0 | AJ20: 0 | AK20: 0 | AL20: 0 | AN20: 0 | AO20: 1459.66 | AP20: 116158.75 | AR20: 0 | AS20: 0 | AT20: 0 | AU20: 0 | AV20: 0 | AW20: 0 | AX20: 0 | AY20: 0 | AZ20: 0 | BA20: 0 | BB20: 0 | BC20: 0 | BD20: CHEMICAL
A21: CH249 | B21: (TEST) SULPHUR 60% 1200 KGS/IBC | C21: Kg | D21: 0 | E21: 0 | F21: 0 | G21: 0 | H21: 0 | I21: 0 | J21: 0 | K21: 0 | L21: 0 | M21: 0 | O21: 0 | P21: 0 | Q21: 0 | R21: 0 | S21: 0 | T21: 0 | U21: 0 | V21: 0 | W21: 0 | X21: 0 | Z21: 0 | AA21: 0 | AC21: 0 | AE21: 0 | AF21: 0 | AG21: 0 | AH21: 0 | AI21: 0 | AJ21: 0 | AK21: 0 | AL21: 0 | AN21: 0 | AO21: 0 | AP21: 0 | AR21: 0 | AS21: 0 | AT21: 0 | AU21: 0 | AV21: 0 | AW21: 0 | AX21: 0 | AY21: 0 | AZ21: 0 | BA21: 0 | BB21: 20 | BC21: 0.08 | BD21: CHEMICAL
A22: CH88 | B22: SURFYNOL DF 37 (DEFORMER) 20KGS./DRUM | C22: Kg | D22: 13 | E22: 7280.02 | F22: 0 | G22: 0 | H22: 0 | I22: 0 | J22: 0 | K22: 0 | L22: 0 | M22: 0 | O22: 0 | P22: 0 | Q22: 0 | R22: 0 | S22: 0 | T22: 0 | U22: 0 | V22: 0 | W22: 0 | X22: 0 | Z22: 0 | AA22: 0 | AC22: 0 | AE22: 0 | AF22: 0 | AG22: 0 | AH22: 0 | AI22: 0 | AJ22: 0 | AK22: 0 | AL22: 0 | AN22: 0 | AO22: 0 | AP22: 0 | AR22: 0 | AS22: 0 | AT22: 0 | AU22: 0 | AV22: 0 | AW22: 0 | AX22: 0 | AY22: 0 | AZ22: 0 | BA22: 13 | BB22: 560.00154 | BC22: 7280.02 | BD22: CHEMICAL
A23: CH91 | B23: ZDBC 50% 225 KGS/DRUM | C23: Kg | D23: 286.5 | E23: 13877.33 | F23: 0 | G23: 0 | H23: 0 | I23: 0 | J23: 900 | K23: 47379.69 | L23: 0 | M23: 0 | O23: 0 | P23: 0 | Q23: 400 | R23: 19722.72 | S23: 0 | T23: 0 | U23: 0 | V23: 0 | W23: 0 | X23: 0 | Z23: 0 | AA23: 0 | AC23: 1090.7 | AD23: =+AE23/AC23 -> 50.317319 | AE23: 54881.1 | AF23: 0 | AG23: 0 | AH23: 0 | AI23: 0 | AJ23: 0 | AK23: 0 | AL23: 0 | AN23: 0 | AO23: 0 | AP23: 0 | AR23: 0 | AS23: 0 | AT23: 0 | AU23: 0 | AV23: 0 | AW23: 0 | AX23: 0 | AY23: 0 | AZ23: 0 | BA23: 495.8 | BB23: 52.639802 | BC23: 26098.64 | BD23: CHEMICAL
A24: CH92 | B24: SULPHUR 60% 250 KGS/DRUM | C24: Kg | D24: 903.29 | E24: 25097.81 | F24: 0 | G24: 0 | H24: 0 | I24: 0 | J24: 2000 | K24: 60426.4 | L24: 0 | M24: 0 | O24: 0 | P24: 0 | Q24: 0 | R24: 0 | S24: 0 | T24: 0 | U24: 0 | V24: 0 | W24: 0 | X24: 0 | Z24: 0 | AA24: 0 | AC24: 1781.29 | AD24: =+AE24/AC24 -> 28.016028 | AE24: 49904.67 | AF24: 0 | AG24: 0 | AH24: 0 | AI24: 0 | AJ24: 0 | AK24: 0 | AL24: 0 | AN24: 0 | AO24: 0 | AP24: 0 | AR24: 0 | AS24: 0 | AT24: 0 | AU24: 0 | AV24: 0 | AW24: 0 | AX24: 0 | AY24: 0 | AZ24: 0 | BA24: 1122 | BB24: 31.746471 | BC24: 35619.54 | BD24: CHEMICAL
A25: CH93 | B25: ZINC OXIDE 60% (ZNO) 250 KGS/DRUM | C25: Kg | D25: 1062 | E25: 73286.82 | F25: 0 | G25: 0 | H25: 0 | I25: 0 | J25: 2000 | K25: 142859.9 | L25: 0 | M25: 0 | O25: 0 | P25: 0 | Q25: 0 | R25: 0 | S25: 0 | T25: 0 | U25: 0 | V25: 0 | W25: 0 | X25: 0 | Z25: 0 | AA25: 0 | AC25: 2259 | AD25: =+AE25/AC25 -> 69.839849 | AE25: 157768.22 | AF25: 0 | AG25: 0 | AH25: 0 | AI25: 0 | AJ25: 0 | AK25: 0 | AL25: 0 | AN25: 0 | AO25: 0 | AP25: 0 | AR25: 0 | AS25: 0 | AT25: 0 | AU25: 0 | AV25: 0 | AW25: 0 | AX25: 0 | AY25: 0 | AZ25: 0 | BA25: 803 | BB25: 72.700833 | BC25: 58378.5 | BD25: CHEMICAL
A26: CH94 | B26: TIO2 70% (TITANIUM DIOXIDE) 250 KGS/DRUM | C26: Kg | D26: 1618.39 | E26: 86203.52 | F26: 0 | G26: 0 | H26: 0 | I26: 0 | J26: 0 | K26: 0 | L26: 0 | M26: 0 | O26: 0 | P26: 0 | Q26: 0 | R26: 0 | S26: 0 | T26: 0 | U26: 0 | V26: 0 | W26: 0 | X26: 0 | Z26: 0 | AA26: 0 | AC26: 720.84 | AD26: =+AE26/AC26 -> 52.941651 | AE26: 38162.46 | AF26: 0 | AG26: 0 | AH26: 0 | AI26: 0 | AJ26: 0 | AK26: 0 | AL26: 0 | AN26: 0 | AO26: 897.55 | AP26: 48041.05 | AR26: 0 | AS26: 0 | AT26: 0 | AU26: 0 | AV26: 0 | AW26: 0 | AX26: 0 | AY26: 0 | AZ26: 0 | BA26: 0 | BB26: 0 | BC26: 0 | BD26: CHEMICAL
B30: Total | D30: =SUM(D7:D29) -> 28730.81 | E30: =SUM(E7:E29) -> 855624.92 | F30: =SUM(F7:F29) -> 5.8 | G30: =SUM(G7:G29) -> 781.78 | H30: =SUM(H7:H29) -> 12507 | I30: =SUM(I7:I29) -> 774259.99 | J30: =SUM(J7:J29) -> 149550 | K30: =SUM(K7:K29) -> 2296974.4 | ... AC30: =SUM(AC7:AC29) -> 174648.8 | AE30: =SUM(AE7:AE29) -> 3200898.4 | AF30: =SUM(AF7:AF29) -> 0 | AG30: =SUM(AG7:AG29) -> 0 | AH30: =SUM(AH7:AH29) -> 0 | AI30: =SUM(AI7:AI29) -> 0 | AJ30: =SUM(AJ7:AJ29) -> 0 | AK30: =SUM(AK7:AK29) -> 0 | AL30: =SUM(AL7:AL29) -> 0 | ... BA30: =SUM(BA7:BA29) -> 13940.19 | BC30: =SUM(BC7:BC29) -> 524568.67
C32: check | D32: 28730.81 | E32: 855624.92 | BA32: =+D30+F30+H30+J30+L30+Q30+S30-AC30-AO30 -> 13940.19 | BC32: =+E30+G30+I30+K30+M30+R30-AE30-AP30-AS30+T30+0.13 -> 524568.67
BA34: =+BA30-BA32 -> 1.8189894e-11 | BC34: =+BC30-BC32 -> 0

Sheet Che.-Prod
A1: Mercator Medical (Thailand) LTD.
A2: Stock Card Report By Location
A3: From 01-May-26 To 31-May-26 | G3: Costing method: WA | L3: TAX ID : | M3: 0905546002869
A5: Code | B5: Item | C5: UOM | D5: Balance | G5: Received | I5: Transfer from other plant | K5: Issued | M5: Transfer to other plant | O5: Adjustment | P5: Balance
D6: Qty | E6: Unit Cost | F6: Amount | G6: Qty | H6: Amount | I6: Qty | J6: Amount | K6: Qty | L6: Amount | M6: Qty | N6: Amount | O6: Qty | P6: Qty | Q6: Unit Cost | R6: Amount
A7: Production - Plant 1
A9: CH104 | B9: SPECLEAN 11 (246 KGS /DRUM) | C9: Kg | F9: 0 | R9: =P9*Q9 -> 0
A10: CH111 | B10: ALKALINE CLEAN S4 (1100 KG/TANK) | C10: Kg | F10: 0 | R10: =P10*Q10 -> 0
A11: CH196 | B11: TEXKLEEN P22 (225KG/DRUM)(ALKALINE CLEANER ) | C11: Kg | D11: 1800 | E11: 10.5 | F11: 18900 | P11: 450 | Q11: 10.5 | R11: =P11*Q11 -> 4725
A12: CH26 | B12: NITRIC ACID 68% (280 KGS/DRUM ) | C12: Kg | D12: 1960 | E12: 13 | F12: 25480 | P12: 1120 | Q12: 13 | R12: =P12*Q12 -> 14560
A13: CH23 | B13: AMMONIUM HYDROXIDE 180KGS /DRUM | C13: Kg | D13: 720 | E13: 16.2 | F13: 11664 | P13: 720 | Q13: 16.2 | R13: =P13*Q13 -> 11664
A14: CH209 | B14: (TEST) SPECLEAN8 (240KG/DRUM) - ALKALINE CLEANER | C14: Kg | E14: 15.5 | F14: 0 | Q14: =SUMIF('Che-Store'!A10:A15,'Che.-Prod'!A12,'Che-Store'!AD10:AD15) -> 15.5 | R14: =P14*Q14 -> 0
A15: CH252 | B15: (TEST) KLEEN S21 (225KG/DRUM) (ALAKLINE CLEANNER) | C15: Kg | D15: 1125 | E15: 10.35 | F15: 11643.75 | Q15: 10.35 | R15: =P15*Q15 -> 0
A16: CH245 | B16: (TEST) SPECLEAN 10 (230KG/DRUM) - ALKALINE CLEANER | C16: Kg | P16: 1150 | Q16: 9.58 | R16: =P16*Q16 -> 11017
D18: 5605 | F18: 67687.75 | I18: 0 | J18: 0 | K18: 0 | L18: 0 | P18: =SUM(P9:P17) -> 3440 | R18: =SUM(R9:R17) -> 41966
C20: checked | D20: 5605 | F20: 67687.75 | P20: =P18 -> 3440 | R20: =R18 -> 41966

Sheet BalCom
C1: Balance Compound latex
C3: Name | D3: Master name | E3: Item Name | F3: Code | G3: TSC | H3: Dry Kg | I3: Balance (Kg) | J3: Column1 | K3: Total Dry Kg | L3: Bal. Kg Dry | M3: Bal. Kg Wet | N3: New Code | O3: Price | P3: Cost (Baht) | Q3: **Check**
A4: =IF(LEFT(BalCom[[#This Row],[Code]],3)="NBR","NBR","CHE") -> NBR | C4: _BalCom | D4: PLANT#1 FINGER TEXTURE BLACK 6.0G WITH BST8503S+NEOPELEX+15PHR MRC+AQUAWAX NITRILE COMPOUND | E4: NBR01 - SYNTHETIC LATEX BST NBL 8503S | F4: NBR01 | G4: 0.4496 | H4: 1818 | I4: 2183.692 | K4: =SUMIFS(H:H,C:C,BalCom[[#This Row],[Name]],D:D,BalCom[[#This Row],[Master name]]) -> 2201.598 | L4: =IFERROR(BalCom[[#This Row],[Balance (Kg)]]*BalCom[[#This Row],[Dry Kg]]/BalCom[[#This Row],[Total Dry Kg]],0) -> 1803.2139 | M4: =IF(D4="","",BalCom[[#This Row],[Bal. Kg Dry]]/BalCom[[#This Row],[TSC]]) -> 4010.707 | N4: =IF(_xlfn.XLOOKUP(BalCom[[#This Row],[Code]],Info!B:B,Info!D:D,0)=0,BalCom[[#This Row],[Code]],(_xlfn.XLOOKUP(BalCom[[#This Row],[Code]],Info!B:B,Info!D:D,0))) -> NBR01 | O4: =IF(BalCom[[#This Row],[New Code]]="SFG-Water",0,_xlfn.XLOOKUP(BalCom[[#This Row],[New Code]],Used_before_Trf!A:A,Used_before_Trf!U:U,"")) -> 50.516914 | P4: =IF(D4="","",ROUND((BalCom[[#This Row],[Price]]*BalCom[[#This Row],[Bal. Kg Wet]]),2)) -> 202608.54 | Q4: =IF(BalCom[[#This Row],[Master name]]="","",IF(N4="SFG-Water","",IF(AND(N4<>0,P4<>0),"Ok","Error"))) -> Ok
A5: =IF(LEFT(BalCom[[#This Row],[Code]],3)="NBR","NBR","CHE") -> CHE | C5: _BalCom | D5: PLANT#1 FINGER TEXTURE BLACK 6.0G WITH BST8503S+NEOPELEX+15PHR MRC+AQUAWAX NITRILE COMPOUND | E5: CH148 - KOH 48% SOLUTION (1500KG/IBC) (TC GROUP) (POTASSIUM HYDROXIDE) | F5: CH212 | G5: 0.03 | H5: 1.8699312 | I5: 2183.692 | K5: =SUMIFS(H:H,C:C,BalCom[[#This Row],[Name]],D:D,BalCom[[#This Row],[Master name]]) -> 2201.598 | L5: =IFERROR(BalCom[[#This Row],[Balance (Kg)]]*BalCom[[#This Row],[Dry Kg]]/BalCom[[#This Row],[Total Dry Kg]],0) -> 1.8547227 | M5: =IF(D5="","",BalCom[[#This Row],[Bal. Kg Dry]]/BalCom[[#This Row],[TSC]]) -> 61.824089 | N5: =IF(_xlfn.XLOOKUP(BalCom[[#This Row],[Code]],Info!B:B,Info!D:D,0)=0,BalCom[[#This Row],[Code]],(_xlfn.XLOOKUP(BalCom[[#This Row],[Code]],Info!B:B,Info!D:D,0))) -> CH212 | O5: =IF(BalCom[[#This Row],[New Code]]="SFG-Water",0,_xlfn.XLOOKUP(BalCom[[#This Row],[New Code]],Used_before_Trf!A:A,Used_before_Trf!U:U,"")) -> 32.035421 | P5: =IF(D5="","",ROUND((BalCom[[#This Row],[Price]]*BalCom[[#This Row],[Bal. Kg Wet]]),2)) -> 1980.56 | Q5: =IF(BalCom[[#This Row],[Master name]]="","",IF(N5="SFG-Water","",IF(AND(N5<>0,P5<>0),"Ok","Error"))) -> Ok
A6: =IF(LEFT(BalCom[[#This Row],[Code]],3)="NBR","NBR","CHE") -> CHE | C6: _BalCom | D6: PLANT#1 FINGER TEXTURE BLACK 6.0G WITH BST8503S+NEOPELEX+15PHR MRC+AQUAWAX NITRILE COMPOUND | E6: SFG-Water - WATER FOR COMPOUND ONLY | F6: SFG-Water | G6: 0.03 | H6: 25.400069 | I6: 2183.692 | K6: =SUMIFS(H:H,C:C,BalCom[[#This Row],[Name]],D:D,BalCom[[#This Row],[Master name]]) -> 2201.598 | L6: =IFERROR(BalCom[[#This Row],[Balance (Kg)]]*BalCom[[#This Row],[Dry Kg]]/BalCom[[#This Row],[Total Dry Kg]],0) -> 25.193485 | M6: =IF(D6="","",BalCom[[#This Row],[Bal. Kg Dry]]/BalCom[[#This Row],[TSC]]) -> 839.78285 | N6: =IF(_xlfn.XLOOKUP(BalCom[[#This Row],[Code]],Info!B:B,Info!D:D,0)=0,BalCom[[#This Row],[Code]],(_xlfn.XLOOKUP(BalCom[[#This Row],[Code]],Info!B:B,Info!D:D,0))) -> SFG-Water | O6: =IF(BalCom[[#This Row],[New Code]]="SFG-Water",0,_xlfn.XLOOKUP(BalCom[[#This Row],[New Code]],Used_before_Trf!A:A,Used_before_Trf!U:U,"")) -> 0 | P6: =IF(D6="","",ROUND((BalCom[[#This Row],[Price]]*BalCom[[#This Row],[Bal. Kg Wet]]),2)) -> 0 | Q6: =IF(BalCom[[#This Row],[Master name]]="","",IF(N6="SFG-Water","",IF(AND(N6<>0,P6<>0),"Ok","Error")))
A7: =IF(LEFT(BalCom[[#This Row],[Code]],3)="NBR","NBR","CHE") -> CHE | C7: _BalCom | D7: PLANT#1 FINGER TEXTURE BLACK 6.0G WITH BST8503S+NEOPELEX+15PHR MRC+AQUAWAX NITRILE COMPOUND | E7: CH227 - NEOPELEX G-15P (1000KG/IBC) (SDBS) | F7: CH227 | G7: 0.15 | H7: 3.636 | I7: 2183.692 | K7: =SUMIFS(H:H,C:C,BalCom[[#This Row],[Name]],D:D,BalCom[[#This Row],[Master name]]) -> 2201.598 | L7: =IFERROR(BalCom[[#This Row],[Balance (Kg)]]*BalCom[[#This Row],[Dry Kg]]/BalCom[[#This Row],[Total Dry Kg]],0) -> 3.6064277 | M7: =IF(D7="","",BalCom[[#This Row],[Bal. Kg Dry]]/BalCom[[#This Row],[TSC]]) -> 24.042852 | N7: =IF(_xlfn.XLOOKUP(BalCom[[#This Row],[Code]],Info!B:B,Info!D:D,0)=0,BalCom[[#This Row],[Code]],(_xlfn.XLOOKUP(BalCom[[#This Row],[Code]],Info!B:B,Info!D:D,0))) -> CH227 | O7: =IF(BalCom[[#This Row],[New Code]]="SFG-Water",0,_xlfn.XLOOKUP(BalCom[[#This Row],[New Code]],Used_before_Trf!A:A,Used_before_Trf!U:U,"")) -> 14.05404 | P7: =IF(D7="","",ROUND((BalCom[[#This Row],[Price]]*BalCom[[#This Row],[Bal. Kg Wet]]),2)) -> 337.9 | Q7: =IF(BalCom[[#This Row],[Master name]]="","",IF(N7="SFG-Water","",IF(AND(N7<>0,P7<>0),"Ok","Error"))) -> Ok
A8: =IF(LEFT(BalCom[[#This Row],[Code]],3)="NBR","NBR","CHE") -> CHE | C8: _BalCom | D8: PLANT#1 FINGER TEXTURE BLACK 6.0G WITH BST8503S+NEOPELEX+15PHR MRC+AQUAWAX NITRILE COMPOUND | E8: CH93 - ZINC OXIDE 60% (ZNO) 250 KGS/DRUM | F8: CH93 | G8: 0.6 | H8: 14.544 | I8: 2183.692 | K8: =SUMIFS(H:H,C:C,BalCom[[#This Row],[Name]],D:D,BalCom[[#This Row],[Master name]]) -> 2201.598 | L8: =IFERROR(BalCom[[#This Row],[Balance (Kg)]]*BalCom[[#This Row],[Dry Kg]]/BalCom[[#This Row],[Total Dry Kg]],0) -> 14.425711 | M8: =IF(D8="","",BalCom[[#This Row],[Bal. Kg Dry]]/BalCom[[#This Row],[TSC]]) -> 24.042852 | N8: =IF(_xlfn.XLOOKUP(BalCom[[#This Row],[Code]],Info!B:B,Info!D:D,0)=0,BalCom[[#This Row],[Code]],(_xlfn.XLOOKUP(BalCom[[#This Row],[Code]],Info!B:B,Info!D:D,0))) -> CH93 | O8: =IF(BalCom[[#This Row],[New Code]]="SFG-Water",0,_xlfn.XLOOKUP(BalCom[[#This Row],[New Code]],Used_before_Trf!A:A,Used_before_Trf!U:U,"")) -> 69.839849 | P8: =IF(D8="","",ROUND((BalCom[[#This Row],[Price]]*BalCom[[#This Row],[Bal. Kg Wet]]),2)) -> 1679.15 | Q8: =IF(BalCom[[#This Row],[Master name]]="","",IF(N8="SFG-Water","",IF(AND(N8<>0,P8<>0),"Ok","Error"))) -> Ok
A9: =IF(LEFT(BalCom[[#This Row],[Code]],3)="NBR","NBR","CHE") -> CHE | C9: _BalCom | D9: PLANT#1 FINGER TEXTURE BLACK 6.0G WITH BST8503S+NEOPELEX+15PHR MRC+AQUAWAX NITRILE COMPOUND | E9: CH92 - SULPHUR 60% 250 KGS/DRUM | F9: CH92 | G9: 0.6 | H9: 18.18 | I9: 2183.692 | K9: =SUMIFS(H:H,C:C,BalCom[[#This Row],[Name]],D:D,BalCom[[#This Row],[Master name]]) -> 2201.598 | L9: =IFERROR(BalCom[[#This Row],[Balance (Kg)]]*BalCom[[#This Row],[Dry Kg]]/BalCom[[#This Row],[Total Dry Kg]],0) -> 18.032139 | M9: =IF(D9="","",BalCom[[#This Row],[Bal. Kg Dry]]/BalCom[[#This Row],[TSC]]) -> 30.053565 | N9: =IF(_xlfn.XLOOKUP(BalCom[[#This Row],[Code]],Info!B:B,Info!D:D,0)=0,BalCom[[#This Row],[Code]],(_xlfn.XLOOKUP(BalCom[[#This Row],[Code]],Info!B:B,Info!D:D,0))) -> CH92 | O9: =IF(BalCom[[#This Row],[New Code]]="SFG-Water",0,_xlfn.XLOOKUP(BalCom[[#This Row],[New Code]],Used_before_Trf!A:A,Used_before_Trf!U:U,"")) -> 28.016028 | P9: =IF(D9="","",ROUND((BalCom[[#This Row],[Price]]*BalCom[[#This Row],[Bal. Kg Wet]]),2)) -> 841.98 | Q9: =IF(BalCom[[#This Row],[Master name]]="","",IF(N9="SFG-Water","",IF(AND(N9<>0,P9<>0),"Ok","Error"))) -> Ok
A10: =IF(LEFT(BalCom[[#This Row],[Code]],3)="NBR","NBR","CHE") -> CHE | C10: _BalCom | D10: PLANT#1 FINGER TEXTURE BLACK 6.0G WITH BST8503S+NEOPELEX+15PHR MRC+AQUAWAX NITRILE COMPOUND | E10: CH91 - ZDBC 50% 225 KGS/DRUM | F10: CH91 | G10: 0.5 | H10: 10.908 | I10: 2183.692 | K10: =SUMIFS(H:H,C:C,BalCom[[#This Row],[Name]],D:D,BalCom[[#This Row],[Master name]]) -> 2201.598 | L10: =IFERROR(BalCom[[#This Row],[Balance (Kg)]]*BalCom[[#This Row],[Dry Kg]]/BalCom[[#This Row],[Total Dry Kg]],0) -> 10.819283 | M10: =IF(D10="","",BalCom[[#This Row],[Bal. Kg Dry]]/BalCom[[#This Row],[TSC]]) -> 21.638566 | N10: =IF(_xlfn.XLOOKUP(BalCom[[#This Row],[Code]],Info!B:B,Info!D:D,0)=0,BalCom[[#This Row],[Code]],(_xlfn.XLOOKUP(BalCom[[#This Row],[Code]],Info!B:B,Info!D:D,0))) -> CH91 | O10: =IF(BalCom[[#This Row],[New Code]]="SFG-Water",0,_xlfn.XLOOKUP(BalCom[[#This Row],[New Code]],Used_before_Trf!A:A,Used_before_Trf!U:U,"")) -> 50.317319 | P10: =IF(D10="","",ROUND((BalCom[[#This Row],[Price]]*BalCom[[#This Row],[Bal. Kg Wet]]),2)) -> 1088.79 | Q10: =IF(BalCom[[#This Row],[Master name]]="","",IF(N10="SFG-Water","",IF(AND(N10<>0,P10<>0),"Ok","Error"))) -> Ok
A11: =IF(LEFT(BalCom[[#This Row],[Code]],3)="NBR","NBR","CHE") -> CHE | C11: _BalCom | D11: PLANT#1 FINGER TEXTURE BLACK 6.0G WITH BST8503S+NEOPELEX+15PHR MRC+AQUAWAX NITRILE COMPOUND | E11: CH229 - MRC600NB50(1400KG/IBC) MOQ: 22,400KG EXTENDER | F11: CH229 | G11: 0.45 | H11: 272.7 | I11: 2183.692 | K11: =SUMIFS(H:H,C:C,BalCom[[#This Row],[Name]],D:D,BalCom[[#This Row],[Master name]]) -> 2201.598 | L11: =IFERROR(BalCom[[#This Row],[Balance (Kg)]]*BalCom[[#This Row],[Dry Kg]]/BalCom[[#This Row],[Total Dry Kg]],0) -> 270.48208 | M11: =IF(D11="","",BalCom[[#This Row],[Bal. Kg Dry]]/BalCom[[#This Row],[TSC]]) -> 601.07129 | N11: =IF(_xlfn.XLOOKUP(BalCom[[#This Row],[Code]],Info!B:B,Info!D:D,0)=0,BalCom[[#This Row],[Code]],(_xlfn.XLOOKUP(BalCom[[#This Row],[Code]],Info!B:B,Info!D:D,0))) -> CH229 | O11: =IF(BalCom[[#This Row],[New Code]]="SFG-Water",0,_xlfn.XLOOKUP(BalCom[[#This Row],[New Code]],Used_before_Trf!A:A,Used_before_Trf!U:U,"")) -> 13.07 | P11: =IF(D11="","",ROUND((BalCom[[#This Row],[Price]]*BalCom[[#This Row],[Bal. Kg Wet]]),2)) -> 7856 | Q11: =IF(BalCom[[#This Row],[Master name]]="","",IF(N11="SFG-Water","",IF(AND(N11<>0,P11<>0),"Ok","Error"))) -> Ok
A12: =IF(LEFT(BalCom[[#This Row],[Code]],3)="NBR","NBR","CHE") -> CHE | C12: _BalCom | D12: PLANT#1 FINGER TEXTURE BLACK 6.0G WITH BST8503S+NEOPELEX+15PHR MRC+AQUAWAX NITRILE COMPOUND | E12: CH222 - AQUAWAX 022S (950KG/IBC) -WAX | F12: CH222 | G12: 0.55 | H12: 18.18 | I12: 2183.692 | K12: =SUMIFS(H:H,C:C,BalCom[[#This Row],[Name]],D:D,BalCom[[#This Row],[Master name]]) -> 2201.598 | L12: =IFERROR(BalCom[[#This Row],[Balance (Kg)]]*BalCom[[#This Row],[Dry Kg]]/BalCom[[#This Row],[Total Dry Kg]],0) -> 18.032139 | M12: =IF(D12="","",BalCom[[#This Row],[Bal. Kg Dry]]/BalCom[[#This Row],[TSC]]) -> 32.785707 | N12: =IF(_xlfn.XLOOKUP(BalCom[[#This Row],[Code]],Info!B:B,Info!D:D,0)=0,BalCom[[#This Row],[Code]],(_xlfn.XLOOKUP(BalCom[[#This Row],[Code]],Info!B:B,Info!D:D,0))) -> CH222 | O12: =IF(BalCom[[#This Row],[New Code]]="SFG-Water",0,_xlfn.XLOOKUP(BalCom[[#This Row],[New Code]],Used_before_Trf!A:A,Used_before_Trf!U:U,"")) -> 42.341881 | P12: =IF(D12="","",ROUND((BalCom[[#This Row],[Price]]*BalCom[[#This Row],[Bal. Kg Wet]]),2)) -> 1388.21 | Q12: =IF(BalCom[[#This Row],[Master name]]="","",IF(N12="SFG-Water","",IF(AND(N12<>0,P12<>0),"Ok","Error"))) -> Ok
A13: =IF(LEFT(BalCom[[#This Row],[Code]],3)="NBR","NBR","CHE") -> CHE | C13: _BalCom | D13: PLANT#1 FINGER TEXTURE BLACK 6.0G WITH BST8503S+NEOPELEX+15PHR MRC+AQUAWAX NITRILE COMPOUND | E13: CH199 - FARSPERSE BLACK PB-ZBX SF (20 KGS/PAIL) (PIGMENT SILICONE FREE) | F13: CH140 | G13: 0.5 | H13: 18.18 | I13: 2183.692 | K13: =SUMIFS(H:H,C:C,BalCom[[#This Row],[Name]],D:D,BalCom[[#This Row],[Master name]]) -> 2201.598 | L13: =IFERROR(BalCom[[#This Row],[Balance (Kg)]]*BalCom[[#This Row],[Dry Kg]]/BalCom[[#This Row],[Total Dry Kg]],0) -> 18.032139 | M13: =IF(D13="","",BalCom[[#This Row],[Bal. Kg Dry]]/BalCom[[#This Row],[TSC]]) -> 36.064277 | N13: =IF(_xlfn.XLOOKUP(BalCom[[#This Row],[Code]],Info!B:B,Info!D:D,0)=0,BalCom[[#This Row],[Code]],(_xlfn.XLOOKUP(BalCom[[#This Row],[Code]],Info!B:B,Info!D:D,0))) -> CH140 | O13: =IF(BalCom[[#This Row],[New Code]]="SFG-Water",0,_xlfn.XLOOKUP(BalCom[[#This Row],[New Code]],Used_before_Trf!A:A,Used_before_Trf!U:U,"")) -> 57.918555 | P13: =IF(D13="","",ROUND((BalCom[[#This Row],[Price]]*BalCom[[#This Row],[Bal. Kg Wet]]),2)) -> 2088.79 | Q13: =IF(BalCom[[#This Row],[Master name]]="","",IF(N13="SFG-Water","",IF(AND(N13<>0,P13<>0),"Ok","Error"))) -> Ok
A14: =IF(LEFT(BalCom[[#This Row],[Code]],3)="NBR","NBR","CHE") -> NBR | C14: _BalCom | D14: PLANT#1 FINGER TEXTURE BLACK 6.0G WITH BST8503S+NEOPELEX+15PHR MRC NITRILE COMPOUND-DIP2 | E14: NBR01 - SYNTHETIC LATEX BST NBL 8503S | F14: NBR01 | G14: 0.4496 | H14: 1827 | I14: 2027.936 | K14: =SUMIFS(H:H,C:C,BalCom[[#This Row],[Name]],D:D,BalCom[[#This Row],[Master name]]) -> 2199.708 | L14: =IFERROR(BalCom[[#This Row],[Balance (Kg)]]*BalCom[[#This Row],[Dry Kg]]/BalCom[[#This Row],[Total Dry Kg]],0) -> 1684.3322 | M14: =IF(D14="","",BalCom[[#This Row],[Bal. Kg Dry]]/BalCom[[#This Row],[TSC]]) -> 3746.2905 | N14: =IF(_xlfn.XLOOKUP(BalCom[[#This Row],[Code]],Info!B:B,Info!D:D,0)=0,BalCom[[#This Row],[Code]],(_xlfn.XLOOKUP(BalCom[[#This Row],[Code]],Info!B:B,Info!D:D,0))) -> NBR01 | O14: =IF(BalCom[[#This Row],[New Code]]="SFG-Water",0,_xlfn.XLOOKUP(BalCom[[#This Row],[New Code]],Used_before_Trf!A:A,Used_before_Trf!U:U,"")) -> 50.516914 | P14: =IF(D14="","",ROUND((BalCom[[#This Row],[Price]]*BalCom[[#This Row],[Bal. Kg Wet]]),2)) -> 189251.04 | Q14: =IF(BalCom[[#This Row],[Master name]]="","",IF(N14="SFG-Water","",IF(AND(N14<>0,P14<>0),"Ok","Error"))) -> Ok
A15: =IF(LEFT(BalCom[[#This Row],[Code]],3)="NBR","NBR","CHE") -> CHE | C15: _BalCom | D15: PLANT#1 FINGER TEXTURE BLACK 6.0G WITH BST8503S+NEOPELEX+15PHR MRC NITRILE COMPOUND-DIP2 | E15: CH148 - KOH 48% SOLUTION (1500KG/IBC) (TC GROUP) (POTASSIUM HYDROXIDE) | F15: CH212 | G15: 0.03 | H15: 2.1297467 | I15: 2027.936 | K15: =SUMIFS(H:H,C:C,BalCom[[#This Row],[Name]],D:D,BalCom[[#This Row],[Master name]]) -> 2199.708 | L15: =IFERROR(BalCom[[#This Row],[Balance (Kg)]]*BalCom[[#This Row],[Dry Kg]]/BalCom[[#This Row],[Total Dry Kg]],0) -> 1.9634379 | M15: =IF(D15="","",BalCom[[#This Row],[Bal. Kg Dry]]/BalCom[[#This Row],[TSC]]) -> 65.447929 | N15: =IF(_xlfn.XLOOKUP(BalCom[[#This Row],[Code]],Info!B:B,Info!D:D,0)=0,BalCom[[#This Row],[Code]],(_xlfn.XLOOKUP(BalCom[[#This Row],[Code]],Info!B:B,Info!D:D,0))) -> CH212 | O15: =IF(BalCom[[#This Row],[New Code]]="SFG-Water",0,_xlfn.XLOOKUP(BalCom[[#This Row],[New Code]],Used_before_Trf!A:A,Used_before_Trf!U:U,"")) -> 32.035421 | P15: =IF(D15="","",ROUND((BalCom[[#This Row],[Price]]*BalCom[[#This Row],[Bal. Kg Wet]]),2)) -> 2096.65 | Q15: =IF(BalCom[[#This Row],[Master name]]="","",IF(N15="SFG-Water","",IF(AND(N15<>0,P15<>0),"Ok","Error"))) -> Ok
